

time.struct_time(tm_year=2018, tm_mon=4, tm_mday=5, tm_hour=13, tm_min=48, tm_sec=21, tm_wday=3, tm_yday=95, tm_isdst=0)
Traceback (most recent call last):
  File "main.py", line 314, in <module>
    test_it_with_bp(play=1, NGEN=100, MU=4 * 25, play_with_whole_pareto=1, post_st = post_st)
  File "main.py", line 301, in test_it_with_bp
    network_obj_tar.test_err(min(pop, key=lambda x: x.fitness.values[1])))
NameError: name 'network_obj_tar' is not defined




time.struct_time(tm_year=2018, tm_mon=4, tm_mday=5, tm_hour=14, tm_min=35, tm_sec=3, tm_wday=3, tm_yday=95, tm_isdst=0)
Traceback (most recent call last):
  File "main.py", line 314, in <module>
    test_it_with_bp(play=1, NGEN=100, MU=4 * 25, play_with_whole_pareto=1, post_st = post_st)
  File "main.py", line 301, in test_it_with_bp
    network_obj_tar.test_err(min(pop, key=lambda x: x.fitness.values[1])))
NameError: name 'network_obj_tar' is not defined




time.struct_time(tm_year=2018, tm_mon=4, tm_mday=5, tm_hour=14, tm_min=36, tm_sec=13, tm_wday=3, tm_yday=95, tm_isdst=0)
Traceback (most recent call last):
  File "main.py", line 314, in <module>
    test_it_with_bp(play=1, NGEN=100, MU=4 * 25, play_with_whole_pareto=1, post_st = post_st)
  File "main.py", line 301, in test_it_with_bp
    network_obj_tar.test_err(min(pop, key=lambda x: x.fitness.values[1])))
NameError: name 'network_obj_tar' is not defined




time.struct_time(tm_year=2018, tm_mon=4, tm_mday=5, tm_hour=22, tm_min=32, tm_sec=24, tm_wday=3, tm_yday=95, tm_isdst=0)
Traceback (most recent call last):
  File "main.py", line 314, in <module>
    test_it_with_bp(play=1, NGEN=100, MU=4 * 25, play_with_whole_pareto=1, post_st = post_st)
  File "main.py", line 280, in test_it_with_bp
    pop, stats = main(play=play, NGEN=NGEN, MU=MU)
  File "main.py", line 102, in main
    for ind, fit in zip(invalid_ind, fitnesses):
  File "main.py", line 36, in minimize_src
    outputarr = network_obj_src.feedforward_ne(individual, final_activation=network.softmax)
  File "/home/placements2018/Desktop/neuro-evolution/network.py", line 209, in feedforward_ne
    storage[tup[1].node_num] += storage[tup[0].node_num]*weight
IndexError: index 325 is out of bounds for axis 0 with size 174




time.struct_time(tm_year=2018, tm_mon=4, tm_mday=5, tm_hour=22, tm_min=33, tm_sec=53, tm_wday=3, tm_yday=95, tm_isdst=0)
Traceback (most recent call last):
  File "main.py", line 314, in <module>
    test_it_with_bp(play=1, NGEN=100, MU=4 * 25, play_with_whole_pareto=1, post_st = post_st)
  File "main.py", line 280, in test_it_with_bp
    pop, stats = main(play=play, NGEN=NGEN, MU=MU)
  File "main.py", line 102, in main
    for ind, fit in zip(invalid_ind, fitnesses):
  File "main.py", line 36, in minimize_src
    outputarr = network_obj_src.feedforward_ne(individual, final_activation=network.softmax)
  File "/home/placements2018/Desktop/neuro-evolution/network.py", line 209, in feedforward_ne
    storage[tup[1].node_num] += storage[tup[0].node_num]*weight
IndexError: index 325 is out of bounds for axis 0 with size 174




time.struct_time(tm_year=2018, tm_mon=4, tm_mday=15, tm_hour=21, tm_min=53, tm_sec=49, tm_wday=6, tm_yday=105, tm_isdst=0)
Traceback (most recent call last):
  File "main.py", line 313, in <module>
    post_st = sys.argv[1]
IndexError: list index out of range




time.struct_time(tm_year=2018, tm_mon=4, tm_mday=15, tm_hour=21, tm_min=56, tm_sec=4, tm_wday=6, tm_yday=105, tm_isdst=0)
Traceback (most recent call last):
  File "main.py", line 314, in <module>
    test_it_with_bp(play=1, NGEN=10, MU=4 * 5, play_with_whole_pareto=1, post_st = post_st)
  File "main.py", line 280, in test_it_with_bp
    pop, stats = main(play=play, NGEN=NGEN, MU=MU)
  File "main.py", line 81, in main
    stats = tools.Statistics(lambda ind: ind.fitness.values[0], ind.fitness.values[1], ind.fitness.values[2])
UnboundLocalError: local variable 'ind' referenced before assignment




time.struct_time(tm_year=2018, tm_mon=4, tm_mday=15, tm_hour=21, tm_min=57, tm_sec=28, tm_wday=6, tm_yday=105, tm_isdst=0)
Traceback (most recent call last):
  File "main.py", line 314, in <module>
    test_it_with_bp(play=1, NGEN=10, MU=4 * 5, play_with_whole_pareto=1, post_st = post_st)
  File "main.py", line 280, in test_it_with_bp
    pop, stats = main(play=play, NGEN=NGEN, MU=MU)
  File "main.py", line 188, in main
    mse = float(liso[3])
ValueError: could not convert string to float: '[  1.62706134 342.99776082 160.        ]'




time.struct_time(tm_year=2018, tm_mon=4, tm_mday=21, tm_hour=1, tm_min=47, tm_sec=25, tm_wday=5, tm_yday=111, tm_isdst=0)
Traceback (most recent call last):
  File "main.py", line 314, in <module>
    test_it_with_bp(play=1, NGEN=10, MU=4 * 5, play_with_whole_pareto=1, post_st = post_st)
  File "main.py", line 280, in test_it_with_bp
    pop, stats = main(play=play, NGEN=NGEN, MU=MU)
  File "main.py", line 102, in main
    for ind, fit in zip(invalid_ind, fitnesses):
  File "main.py", line 37, in minimize_src
    outputarr_tar = network_obj_src.feedforward_ne_for_tar(individual, final_activation=network.softmax)
  File "/home/ak/Documents/forgit/Domain-adaptation/network.py", line 150, in feedforward_ne_for_tar
    self.inputarr = self.tar_transformed_restx
AttributeError: 'Neterr' object has no attribute 'tar_transformed_restx'




time.struct_time(tm_year=2018, tm_mon=4, tm_mday=21, tm_hour=1, tm_min=49, tm_sec=18, tm_wday=5, tm_yday=111, tm_isdst=0)
Traceback (most recent call last):
  File "main.py", line 314, in <module>
    test_it_with_bp(play=1, NGEN=10, MU=4 * 5, play_with_whole_pareto=1, post_st = post_st)
  File "main.py", line 302, in test_it_with_bp
    tup = network_obj_src.test_on_pareto_patch_correctone(pareto_front)
  File "/home/ak/Documents/forgit/Domain-adaptation/network.py", line 296, in test_on_pareto_patch_correctone
    assert (arr.shape[0] == 1)
AssertionError




time.struct_time(tm_year=2018, tm_mon=4, tm_mday=21, tm_hour=1, tm_min=50, tm_sec=43, tm_wday=5, tm_yday=111, tm_isdst=0)
Traceback (most recent call last):
  File "main.py", line 314, in <module>
    test_it_with_bp(play=1, NGEN=10, MU=4 * 5, play_with_whole_pareto=1, post_st = post_st)
  File "main.py", line 302, in test_it_with_bp
    tup = network_obj_src.test_on_pareto_patch_correctone(pareto_front)
  File "/home/ak/Documents/forgit/Domain-adaptation/network.py", line 296, in test_on_pareto_patch_correctone
    assert (arr.shape[0] == 1)
AssertionError




time.struct_time(tm_year=2018, tm_mon=4, tm_mday=21, tm_hour=1, tm_min=51, tm_sec=51, tm_wday=5, tm_yday=111, tm_isdst=0)
Traceback (most recent call last):
  File "main.py", line 314, in <module>
    test_it_with_bp(play=1, NGEN=2, MU=4 * 5, play_with_whole_pareto=1, post_st = post_st)
  File "main.py", line 302, in test_it_with_bp
    tup = network_obj_src.test_on_pareto_patch_correctone(pareto_front)
  File "/home/ak/Documents/forgit/Domain-adaptation/network.py", line 297, in test_on_pareto_patch_correctone
    assert (arr.shape[0] == 1)
AssertionError




time.struct_time(tm_year=2018, tm_mon=4, tm_mday=24, tm_hour=21, tm_min=14, tm_sec=26, tm_wday=1, tm_yday=114, tm_isdst=0)
Traceback (most recent call last):
  File "main.py", line 313, in <module>
    post_st = sys.argv[1]
IndexError: list index out of range




time.struct_time(tm_year=2018, tm_mon=4, tm_mday=24, tm_hour=21, tm_min=15, tm_sec=21, tm_wday=1, tm_yday=114, tm_isdst=0)
Traceback (most recent call last):
  File "main.py", line 314, in <module>
    test_it_with_bp(play=1, NGEN=10, MU=4 * 5, play_with_whole_pareto=1, post_st = post_st)
  File "main.py", line 302, in test_it_with_bp
    tup = network_obj_src.test_on_pareto_patch_correctone_weighted(pareto_front)
  File "/Users/swapnilsharma/forgit/Domain-adaptation/network.py", line 338, in test_on_pareto_patch_correctone_weighted
    lis_of_fitness = [ (item.fitness[0], item.fitness[1]) for item in pareto_set ]
  File "/Users/swapnilsharma/forgit/Domain-adaptation/network.py", line 338, in <listcomp>
    lis_of_fitness = [ (item.fitness[0], item.fitness[1]) for item in pareto_set ]
TypeError: 'FitnessMin' object does not support indexing




time.struct_time(tm_year=2018, tm_mon=4, tm_mday=24, tm_hour=21, tm_min=16, tm_sec=54, tm_wday=1, tm_yday=114, tm_isdst=0)
Traceback (most recent call last):
  File "main.py", line 314, in <module>
    test_it_with_bp(play=1, NGEN=10, MU=4 * 5, play_with_whole_pareto=1, post_st = post_st)
  File "main.py", line 302, in test_it_with_bp
    tup = network_obj_src.test_on_pareto_patch_correctone_weighted(pareto_front)
  File "/Users/swapnilsharma/forgit/Domain-adaptation/network.py", line 353, in test_on_pareto_patch_correctone_weighted
    vote = weighted_mean( activated_output_of_all_nn_on_one_data_point, lis_of_fitness, axis = 0)
TypeError: weighted_mean() got an unexpected keyword argument 'axis'


